<?xml version="1.0" ?>
<!-- Generated using onshape-to-robot -->
<!-- Onshape https://cad.onshape.com/documents/93e48abd5146c7d1ed49480b/w/1ec53cad82eaba3f57507604/e/4581709cacf6385ab5fad6e1 -->
<robot name="urdf">
  <!-- Link base -->
  <link name="base">
    <inertial>
      <origin xyz="0 0 0" rpy="0 0 0"/>
      <mass value="1e-09"/>
      <inertia ixx="1e-09" ixy="0" ixz="0" iyy="1e-09" iyz="0" izz="1e-09"/>
    </inertial>
    <!-- Part base -->
    <visual>
      <origin xyz="-1.9787e-05 0.000150165 0.00198512" rpy="-9.86076e-32 -2.67091e-61 -1.24415e-29"/>
      <geometry>
        <mesh filename="package://assets/base.stl"/>
      </geometry>
      <material name="base_material">
        <color rgba="0.615686 0.811765 0.929412 1.0"/>
      </material>
    </visual>
    <collision>
      <origin xyz="-1.9787e-05 0.000150165 0.00198512" rpy="-9.86076e-32 -2.67091e-61 -1.24415e-29"/>
      <geometry>
        <mesh filename="package://assets/base.stl"/>
      </geometry>
    </collision>
  </link>
  <!-- Link shoulder -->
  <link name="shoulder">
    <inertial>
      <origin xyz="0 0 0" rpy="0 0 0"/>
      <mass value="1e-09"/>
      <inertia ixx="1e-09" ixy="0" ixz="0" iyy="1e-09" iyz="0" izz="1e-09"/>
    </inertial>
    <!-- Part shoulder -->
    <visual>
      <origin xyz="0 -0.0165 -0.0225" rpy="-1.5708 -1.5708 0"/>
      <geometry>
        <mesh filename="package://assets/shoulder.stl"/>
      </geometry>
      <material name="shoulder_material">
        <color rgba="0.647059 0.647059 0.647059 1.0"/>
      </material>
    </visual>
    <collision>
      <origin xyz="0 -0.0165 -0.0225" rpy="-1.5708 -1.5708 0"/>
      <geometry>
        <mesh filename="package://assets/shoulder.stl"/>
      </geometry>
    </collision>
  </link>
  <!-- Link arm -->
  <link name="arm">
    <inertial>
      <origin xyz="0 0 0" rpy="0 0 0"/>
      <mass value="1e-09"/>
      <inertia ixx="1e-09" ixy="0" ixz="0" iyy="1e-09" iyz="0" izz="1e-09"/>
    </inertial>
    <!-- Part arm -->
    <visual>
      <origin xyz="6.21722e-18 0.0558498 -0.003" rpy="-6.16298e-33 -0 -2.66498e-31"/>
      <geometry>
        <mesh filename="package://assets/arm.stl"/>
      </geometry>
      <material name="arm_material">
        <color rgba="0.615686 0.811765 0.929412 1.0"/>
      </material>
    </visual>
    <collision>
      <origin xyz="6.21722e-18 0.0558498 -0.003" rpy="-6.16298e-33 -0 -2.66498e-31"/>
      <geometry>
        <mesh filename="package://assets/arm.stl"/>
      </geometry>
    </collision>
  </link>
  <!-- Link head -->
  <link name="head">
    <inertial>
      <origin xyz="0 0 0" rpy="0 0 0"/>
      <mass value="1e-09"/>
      <inertia ixx="1e-09" ixy="0" ixz="0" iyy="1e-09" iyz="0" izz="1e-09"/>
    </inertial>
    <!-- Part head -->
    <visual>
      <origin xyz="0.04625 -0.0015 0.0035" rpy="-1.5708 -1.5708 0"/>
      <geometry>
        <mesh filename="package://assets/head.stl"/>
      </geometry>
      <material name="head_material">
        <color rgba="0.647059 0.647059 0.647059 1.0"/>
      </material>
    </visual>
    <collision>
      <origin xyz="0.04625 -0.0015 0.0035" rpy="-1.5708 -1.5708 0"/>
      <geometry>
        <mesh filename="package://assets/head.stl"/>
      </geometry>
    </collision>
  </link>
  <!-- Joint from arm to head -->
  <joint name="Elbow2" type="revolute">
    <origin xyz="0.0015 0.0751074 0.0185" rpy="-3.14159 -2.69696e-16 1.5708"/>
    <parent link="arm"/>
    <child link="head"/>
    <axis xyz="0 0 1"/>
    <limit effort="10" velocity="10" lower="-1.5708" upper="1.5708"/>
  </joint>
  <!-- Joint from shoulder to arm -->
  <joint name="Elbow1" type="revolute">
    <origin xyz="-1.53144e-18 -0.0035 -0.0319477" rpy="-1.5708 -6.18403e-15 3.14159"/>
    <parent link="shoulder"/>
    <child link="arm"/>
    <axis xyz="0 0 1"/>
    <limit effort="10" velocity="10" lower="-1.5708" upper="1.5708"/>
  </joint>
  <!-- Joint from base to shoulder -->
  <joint name="Base" type="revolute">
    <origin xyz="-1.9787e-05 0.000150165 0.0359851" rpy="-3.14159 -1.0629e-16 -1.66533e-16"/>
    <parent link="base"/>
    <child link="shoulder"/>
    <axis xyz="0 0 1"/>
    <limit effort="10" velocity="10" lower="-1.5708" upper="1.5708"/>
  </joint>
</robot>
